2023-01-30 20:01:40,256 Downloading and reading train artifact
2023-01-30 20:01:42,004 Extracting target from dataframe
2023-01-30 20:01:42,007 Splitting train/val
2023-01-30 20:01:42,071 Setting up pipeline
2023-01-30 20:01:42,084 Fitting
2023-01-30 20:01:47,204 Scoring
/home/bialekm/miniconda3/envs/mlflow-96f17bb36825f5cf7c5c99bfcfb36a9bcad4e437/lib/python3.9/site-packages/mlflow/models/signature.py:130: UserWarning: Hint: Inferred schema contains integer column(s). Integer columns in Python cannot represent missing values. If your input data contains missing values at inference time, it will be encoded as floats and will cause a schema enforcement error. The best way to avoid this problem is to infer the model schema based on a realistic data sample (training dataset) that includes missing values. Alternatively, you can declare integer columns as doubles (float64) whenever these columns may have missing values. See `Handling Integers With Missing Values <https://www.mlflow.org/docs/latest/models.html#handling-integers-with-missing-values>`_ for more details.
  inputs = _infer_schema(model_input)
/home/bialekm/miniconda3/envs/mlflow-96f17bb36825f5cf7c5c99bfcfb36a9bcad4e437/lib/python3.9/site-packages/_distutils_hack/__init__.py:33: UserWarning: Setuptools is replacing distutils.
  warnings.warn("Setuptools is replacing distutils.")
Traceback (most recent call last):
  File "/home/bialekm/miniconda3/envs/mlflow-96f17bb36825f5cf7c5c99bfcfb36a9bcad4e437/lib/python3.9/site-packages/mlflow/sklearn/utils.py", line 852, in _all_estimators
    return all_estimators()
  File "/home/bialekm/miniconda3/envs/mlflow-96f17bb36825f5cf7c5c99bfcfb36a9bcad4e437/lib/python3.9/site-packages/sklearn/utils/__init__.py", line 1145, in all_estimators
    module = import_module(modname)
  File "/home/bialekm/miniconda3/envs/mlflow-96f17bb36825f5cf7c5c99bfcfb36a9bcad4e437/lib/python3.9/importlib/__init__.py", line 127, in import_module
    return _bootstrap._gcd_import(name[level:], package, level)
  File "<frozen importlib._bootstrap>", line 1030, in _gcd_import
  File "<frozen importlib._bootstrap>", line 1007, in _find_and_load
  File "<frozen importlib._bootstrap>", line 986, in _find_and_load_unlocked
  File "<frozen importlib._bootstrap>", line 680, in _load_unlocked
  File "<frozen importlib._bootstrap_external>", line 850, in exec_module
  File "<frozen importlib._bootstrap>", line 228, in _call_with_frames_removed
  File "/home/bialekm/miniconda3/envs/mlflow-96f17bb36825f5cf7c5c99bfcfb36a9bcad4e437/lib/python3.9/site-packages/sklearn/cross_decomposition/__init__.py", line 1, in <module>
    from ._pls import PLSCanonical, PLSRegression, PLSSVD, CCA
  File "/home/bialekm/miniconda3/envs/mlflow-96f17bb36825f5cf7c5c99bfcfb36a9bcad4e437/lib/python3.9/site-packages/sklearn/cross_decomposition/_pls.py", line 12, in <module>
    from scipy.linalg import pinv2, svd
ImportError: cannot import name 'pinv2' from 'scipy.linalg' (/home/bialekm/miniconda3/envs/mlflow-96f17bb36825f5cf7c5c99bfcfb36a9bcad4e437/lib/python3.9/site-packages/scipy/linalg/__init__.py)
During handling of the above exception, another exception occurred:
Traceback (most recent call last):
  File "/home/bialekm/cd0581-building-a-reproducible-model-workflow-exercises/lesson-4-training-validation-experiment-tracking/exercises/exercise_12/starter/random_forest/run.py", line 236, in <module>
    go(args)
  File "/home/bialekm/cd0581-building-a-reproducible-model-workflow-exercises/lesson-4-training-validation-experiment-tracking/exercises/exercise_12/starter/random_forest/run.py", line 64, in go
    export_model(run, pipe, X_val, pred, args.export_artifact)
  File "/home/bialekm/cd0581-building-a-reproducible-model-workflow-exercises/lesson-4-training-validation-experiment-tracking/exercises/exercise_12/starter/random_forest/run.py", line 109, in export_model
    mlflow.sklearn.autolog(serialization_format='cloudpickle')
  File "/home/bialekm/miniconda3/envs/mlflow-96f17bb36825f5cf7c5c99bfcfb36a9bcad4e437/lib/python3.9/site-packages/mlflow/utils/autologging_utils/__init__.py", line 414, in autolog
    return _autolog(*args, **kwargs)
  File "/home/bialekm/miniconda3/envs/mlflow-96f17bb36825f5cf7c5c99bfcfb36a9bcad4e437/lib/python3.9/site-packages/mlflow/sklearn/__init__.py", line 1214, in autolog
    _autolog(
  File "/home/bialekm/miniconda3/envs/mlflow-96f17bb36825f5cf7c5c99bfcfb36a9bcad4e437/lib/python3.9/site-packages/mlflow/sklearn/__init__.py", line 1727, in _autolog
    estimators_to_patch = _gen_estimators_to_patch()
  File "/home/bialekm/miniconda3/envs/mlflow-96f17bb36825f5cf7c5c99bfcfb36a9bcad4e437/lib/python3.9/site-packages/mlflow/sklearn/__init__.py", line 89, in _gen_estimators_to_patch
    _, estimators_to_patch = zip(*_all_estimators())
  File "/home/bialekm/miniconda3/envs/mlflow-96f17bb36825f5cf7c5c99bfcfb36a9bcad4e437/lib/python3.9/site-packages/mlflow/sklearn/utils.py", line 854, in _all_estimators
    return _backported_all_estimators()
  File "/home/bialekm/miniconda3/envs/mlflow-96f17bb36825f5cf7c5c99bfcfb36a9bcad4e437/lib/python3.9/site-packages/mlflow/sklearn/utils.py", line 896, in _backported_all_estimators
    from sklearn.utils.testing import ignore_warnings
ModuleNotFoundError: No module named 'sklearn.utils.testing'