2023-01-30 15:45:03,410 INFO    MainThread:31079 [wandb_setup.py:_flush():68] Configure stats pid to 31079
2023-01-30 15:45:03,410 INFO    MainThread:31079 [wandb_setup.py:_flush():68] Loading settings from /home/bialekm/.config/wandb/settings
2023-01-30 15:45:03,410 INFO    MainThread:31079 [wandb_setup.py:_flush():68] Loading settings from /home/bialekm/cd0581-building-a-reproducible-model-workflow-exercises/lesson-4-training-validation-experiment-tracking/exercises/exercise_11/starter/random_forest/wandb/settings
2023-01-30 15:45:03,410 INFO    MainThread:31079 [wandb_setup.py:_flush():68] Loading settings from environment variables: {'run_group': 'dev', 'project': 'exercise_11', '_require_service': 'True'}
2023-01-30 15:45:03,410 INFO    MainThread:31079 [wandb_setup.py:_flush():68] Inferring run settings from compute environment: {'program_relpath': 'lesson-4-training-validation-experiment-tracking/exercises/exercise_11/starter/random_forest/run.py', 'program': '/home/bialekm/cd0581-building-a-reproducible-model-workflow-exercises/lesson-4-training-validation-experiment-tracking/exercises/exercise_11/starter/random_forest/run.py'}
2023-01-30 15:45:03,410 INFO    MainThread:31079 [wandb_init.py:_log_setup():478] Logging user logs to /home/bialekm/cd0581-building-a-reproducible-model-workflow-exercises/lesson-4-training-validation-experiment-tracking/exercises/exercise_11/starter/random_forest/wandb/run-20230130_154503-aijravxz/logs/debug.log
2023-01-30 15:45:03,410 INFO    MainThread:31079 [wandb_init.py:_log_setup():479] Logging internal logs to /home/bialekm/cd0581-building-a-reproducible-model-workflow-exercises/lesson-4-training-validation-experiment-tracking/exercises/exercise_11/starter/random_forest/wandb/run-20230130_154503-aijravxz/logs/debug-internal.log
2023-01-30 15:45:03,411 INFO    MainThread:31079 [wandb_init.py:init():518] calling init triggers
2023-01-30 15:45:03,411 INFO    MainThread:31079 [wandb_init.py:init():521] wandb.init called with sweep_config: {}
config: {}
2023-01-30 15:45:03,411 INFO    MainThread:31079 [wandb_init.py:init():571] starting backend
2023-01-30 15:45:03,411 INFO    MainThread:31079 [wandb_init.py:init():575] setting up manager
2023-01-30 15:45:03,413 INFO    MainThread:31079 [backend.py:_multiprocessing_setup():106] multiprocessing start_methods=fork,spawn,forkserver, using: spawn
2023-01-30 15:45:03,415 INFO    MainThread:31079 [wandb_init.py:init():582] backend started and connected
2023-01-30 15:45:03,422 INFO    MainThread:31079 [wandb_init.py:init():670] updated telemetry
2023-01-30 15:45:03,435 INFO    MainThread:31079 [wandb_init.py:init():710] communicating run to backend with 60.0 second timeout
2023-01-30 15:45:35,393 INFO    Thread-1  :31079 [retry.py:__call__():169] Retry attempt failed:
Traceback (most recent call last):
  File "/home/bialekm/miniconda3/envs/mlflow-39aa3e680af2f4195fcf30469c71f5f670d48dfb/lib/python3.9/site-packages/urllib3/connection.py", line 174, in _new_conn
    conn = connection.create_connection(
  File "/home/bialekm/miniconda3/envs/mlflow-39aa3e680af2f4195fcf30469c71f5f670d48dfb/lib/python3.9/site-packages/urllib3/util/connection.py", line 95, in create_connection
    raise err
  File "/home/bialekm/miniconda3/envs/mlflow-39aa3e680af2f4195fcf30469c71f5f670d48dfb/lib/python3.9/site-packages/urllib3/util/connection.py", line 85, in create_connection
    sock.connect(sa)
socket.timeout: timed out

During handling of the above exception, another exception occurred:

Traceback (most recent call last):
  File "/home/bialekm/miniconda3/envs/mlflow-39aa3e680af2f4195fcf30469c71f5f670d48dfb/lib/python3.9/site-packages/urllib3/connectionpool.py", line 703, in urlopen
    httplib_response = self._make_request(
  File "/home/bialekm/miniconda3/envs/mlflow-39aa3e680af2f4195fcf30469c71f5f670d48dfb/lib/python3.9/site-packages/urllib3/connectionpool.py", line 386, in _make_request
    self._validate_conn(conn)
  File "/home/bialekm/miniconda3/envs/mlflow-39aa3e680af2f4195fcf30469c71f5f670d48dfb/lib/python3.9/site-packages/urllib3/connectionpool.py", line 1042, in _validate_conn
    conn.connect()
  File "/home/bialekm/miniconda3/envs/mlflow-39aa3e680af2f4195fcf30469c71f5f670d48dfb/lib/python3.9/site-packages/urllib3/connection.py", line 358, in connect
    self.sock = conn = self._new_conn()
  File "/home/bialekm/miniconda3/envs/mlflow-39aa3e680af2f4195fcf30469c71f5f670d48dfb/lib/python3.9/site-packages/urllib3/connection.py", line 179, in _new_conn
    raise ConnectTimeoutError(
urllib3.exceptions.ConnectTimeoutError: (<urllib3.connection.HTTPSConnection object at 0x7f5a3ad64070>, 'Connection to api.wandb.ai timed out. (connect timeout=10)')

During handling of the above exception, another exception occurred:

Traceback (most recent call last):
  File "/home/bialekm/miniconda3/envs/mlflow-39aa3e680af2f4195fcf30469c71f5f670d48dfb/lib/python3.9/site-packages/requests/adapters.py", line 489, in send
    resp = conn.urlopen(
  File "/home/bialekm/miniconda3/envs/mlflow-39aa3e680af2f4195fcf30469c71f5f670d48dfb/lib/python3.9/site-packages/urllib3/connectionpool.py", line 787, in urlopen
    retries = retries.increment(
  File "/home/bialekm/miniconda3/envs/mlflow-39aa3e680af2f4195fcf30469c71f5f670d48dfb/lib/python3.9/site-packages/urllib3/util/retry.py", line 592, in increment
    raise MaxRetryError(_pool, url, error or ResponseError(cause))
urllib3.exceptions.MaxRetryError: HTTPSConnectionPool(host='api.wandb.ai', port=443): Max retries exceeded with url: /graphql (Caused by ConnectTimeoutError(<urllib3.connection.HTTPSConnection object at 0x7f5a3ad64070>, 'Connection to api.wandb.ai timed out. (connect timeout=10)'))

During handling of the above exception, another exception occurred:

Traceback (most recent call last):
  File "/home/bialekm/miniconda3/envs/mlflow-39aa3e680af2f4195fcf30469c71f5f670d48dfb/lib/python3.9/site-packages/wandb/sdk/lib/retry.py", line 128, in __call__
    result = self._call_fn(*args, **kwargs)
  File "/home/bialekm/miniconda3/envs/mlflow-39aa3e680af2f4195fcf30469c71f5f670d48dfb/lib/python3.9/site-packages/wandb/sdk/internal/internal_api.py", line 241, in execute
    return self.client.execute(*args, **kwargs)  # type: ignore
  File "/home/bialekm/miniconda3/envs/mlflow-39aa3e680af2f4195fcf30469c71f5f670d48dfb/lib/python3.9/site-packages/wandb/vendor/gql-0.2.0/wandb_gql/client.py", line 52, in execute
    result = self._get_result(document, *args, **kwargs)
  File "/home/bialekm/miniconda3/envs/mlflow-39aa3e680af2f4195fcf30469c71f5f670d48dfb/lib/python3.9/site-packages/wandb/vendor/gql-0.2.0/wandb_gql/client.py", line 60, in _get_result
    return self.transport.execute(document, *args, **kwargs)
  File "/home/bialekm/miniconda3/envs/mlflow-39aa3e680af2f4195fcf30469c71f5f670d48dfb/lib/python3.9/site-packages/wandb/vendor/gql-0.2.0/wandb_gql/transport/requests.py", line 38, in execute
    request = requests.post(self.url, **post_args)
  File "/home/bialekm/miniconda3/envs/mlflow-39aa3e680af2f4195fcf30469c71f5f670d48dfb/lib/python3.9/site-packages/requests/api.py", line 115, in post
    return request("post", url, data=data, json=json, **kwargs)
  File "/home/bialekm/miniconda3/envs/mlflow-39aa3e680af2f4195fcf30469c71f5f670d48dfb/lib/python3.9/site-packages/requests/api.py", line 59, in request
    return session.request(method=method, url=url, **kwargs)
  File "/home/bialekm/miniconda3/envs/mlflow-39aa3e680af2f4195fcf30469c71f5f670d48dfb/lib/python3.9/site-packages/requests/sessions.py", line 587, in request
    resp = self.send(prep, **send_kwargs)
  File "/home/bialekm/miniconda3/envs/mlflow-39aa3e680af2f4195fcf30469c71f5f670d48dfb/lib/python3.9/site-packages/requests/sessions.py", line 701, in send
    r = adapter.send(request, **kwargs)
  File "/home/bialekm/miniconda3/envs/mlflow-39aa3e680af2f4195fcf30469c71f5f670d48dfb/lib/python3.9/site-packages/requests/adapters.py", line 553, in send
    raise ConnectTimeout(e, request=request)
requests.exceptions.ConnectTimeout: HTTPSConnectionPool(host='api.wandb.ai', port=443): Max retries exceeded with url: /graphql (Caused by ConnectTimeoutError(<urllib3.connection.HTTPSConnection object at 0x7f5a3ad64070>, 'Connection to api.wandb.ai timed out. (connect timeout=10)'))
2023-01-30 15:46:03,481 ERROR   MainThread:31079 [wandb_init.py:init():724] backend process timed out, exiting...
encountered error: Error communicating with wandb process, exiting...
For more info see: https://docs.wandb.ai/library/init#init-start-error
2023-01-30 15:46:03,501 ERROR   MainThread:31079 [wandb_init.py:init():1135] error
Traceback (most recent call last):
  File "/home/bialekm/miniconda3/envs/mlflow-39aa3e680af2f4195fcf30469c71f5f670d48dfb/lib/python3.9/site-packages/wandb/sdk/wandb_init.py", line 1108, in init
    run = wi.init()
  File "/home/bialekm/miniconda3/envs/mlflow-39aa3e680af2f4195fcf30469c71f5f670d48dfb/lib/python3.9/site-packages/wandb/sdk/wandb_init.py", line 742, in init
    raise error
wandb.errors.CommError: Error communicating with wandb process, exiting...
For more info see: https://docs.wandb.ai/library/init#init-start-error
2023-01-30 15:46:09,355 WARNING MsgRouterThr:31079 [router.py:message_loop():77] message_loop has been closed
